[2024-09-24T17:42:13.193+0000] {local_task_job_runner.py:120} INFO - ::group::Pre task execution logs
[2024-09-24T17:42:13.207+0000] {taskinstance.py:2076} INFO - Dependencies all met for dep_context=non-requeueable deps ti=<TaskInstance: random_forest_classifier_dag.prepare_data manual__2024-09-24T17:42:07.196891+00:00 [queued]>
[2024-09-24T17:42:13.214+0000] {taskinstance.py:2076} INFO - Dependencies all met for dep_context=requeueable deps ti=<TaskInstance: random_forest_classifier_dag.prepare_data manual__2024-09-24T17:42:07.196891+00:00 [queued]>
[2024-09-24T17:42:13.216+0000] {taskinstance.py:2306} INFO - Starting attempt 1 of 1
[2024-09-24T17:42:13.227+0000] {taskinstance.py:2330} INFO - Executing <Task(PythonOperator): prepare_data> on 2024-09-24 17:42:07.196891+00:00
[2024-09-24T17:42:13.234+0000] {standard_task_runner.py:64} INFO - Started process 28877 to run task
[2024-09-24T17:42:13.236+0000] {standard_task_runner.py:90} INFO - Running: ['***', 'tasks', 'run', 'random_forest_classifier_dag', 'prepare_data', 'manual__2024-09-24T17:42:07.196891+00:00', '--job-id', '375', '--raw', '--subdir', 'DAGS_FOLDER/***/dags/.ipynb_checkpoints/hw1-checkpoint.py', '--cfg-path', '/tmp/tmp7hwg29zx']
[2024-09-24T17:42:13.238+0000] {standard_task_runner.py:91} INFO - Job 375: Subtask prepare_data
[2024-09-24T17:42:13.279+0000] {task_command.py:426} INFO - Running <TaskInstance: random_forest_classifier_dag.prepare_data manual__2024-09-24T17:42:07.196891+00:00 [running]> on host 82997fc6deb7
[2024-09-24T17:42:13.347+0000] {taskinstance.py:2648} INFO - Exporting env vars: AIRFLOW_CTX_DAG_EMAIL='alexvlg34@gmail.com' AIRFLOW_CTX_DAG_OWNER='Alex Trigolos' AIRFLOW_CTX_DAG_ID='random_forest_classifier_dag' AIRFLOW_CTX_TASK_ID='prepare_data' AIRFLOW_CTX_EXECUTION_DATE='2024-09-24T17:42:07.196891+00:00' AIRFLOW_CTX_TRY_NUMBER='1' AIRFLOW_CTX_DAG_RUN_ID='manual__2024-09-24T17:42:07.196891+00:00'
[2024-09-24T17:42:13.349+0000] {taskinstance.py:430} INFO - ::endgroup::
[2024-09-24T17:42:13.358+0000] {hw1-checkpoint.py:112} INFO - Prepare data...
[2024-09-24T17:42:13.359+0000] {s3.py:1422} INFO - Downloading source S3 file from Bucket testmlops with path AlexTrigolos/RandomForestClassifier/datasets/dataset.pkl
[2024-09-24T17:42:13.367+0000] {base.py:84} INFO - Using connection ID 's3_connection' for task execution.
[2024-09-24T17:42:13.368+0000] {connection_wrapper.py:388} INFO - AWS Connection (conn_id='s3_connection', conn_type='aws') credentials retrieved from login and password.
[2024-09-24T17:42:13.740+0000] {taskinstance.py:441} INFO - ::group::Post task execution logs
[2024-09-24T17:42:13.741+0000] {taskinstance.py:2905} ERROR - Task failed with exception
Traceback (most recent call last):
  File "/home/airflow/.local/lib/python3.10/site-packages/airflow/models/taskinstance.py", line 465, in _execute_task
    result = _execute_callable(context=context, **execute_callable_kwargs)
  File "/home/airflow/.local/lib/python3.10/site-packages/airflow/models/taskinstance.py", line 432, in _execute_callable
    return execute_callable(context=context, **execute_callable_kwargs)
  File "/home/airflow/.local/lib/python3.10/site-packages/airflow/models/baseoperator.py", line 401, in wrapper
    return func(self, *args, **kwargs)
  File "/home/airflow/.local/lib/python3.10/site-packages/airflow/operators/python.py", line 235, in execute
    return_value = self.execute_callable()
  File "/home/airflow/.local/lib/python3.10/site-packages/airflow/operators/python.py", line 252, in execute_callable
    return self.python_callable(*self.op_args, **self.op_kwargs)
  File "/opt/airflow/dags/airflow/dags/.ipynb_checkpoints/hw1-checkpoint.py", line 113, in prepare_data
    data = s3_download_file(kwargs['model_name'], 'dataset')
  File "/opt/airflow/dags/airflow/dags/.ipynb_checkpoints/hw1-checkpoint.py", line 78, in s3_download_file
    buffer = io.BytesIO(s3_object.get()['Body'].read())
AttributeError: 'str' object has no attribute 'get'
[2024-09-24T17:42:13.774+0000] {taskinstance.py:1206} INFO - Marking task as FAILED. dag_id=random_forest_classifier_dag, task_id=prepare_data, run_id=manual__2024-09-24T17:42:07.196891+00:00, execution_date=20240924T174207, start_date=20240924T174213, end_date=20240924T174213
[2024-09-24T17:42:13.787+0000] {logging_mixin.py:188} WARNING - /home/***/.local/lib/python3.10/site-packages/***/utils/email.py:154 RemovedInAirflow3Warning: Fetching SMTP credentials from configuration variables will be deprecated in a future release. Please set credentials using a connection instead.
[2024-09-24T17:42:13.788+0000] {configuration.py:1053} WARNING - section/key [smtp/smtp_user] not found in config
[2024-09-24T17:42:13.789+0000] {email.py:271} INFO - Email alerting: attempt 1
[2024-09-24T17:42:13.796+0000] {configuration.py:1053} WARNING - section/key [smtp/smtp_user] not found in config
[2024-09-24T17:42:13.797+0000] {email.py:271} INFO - Email alerting: attempt 1
[2024-09-24T17:42:13.798+0000] {taskinstance.py:879} ERROR - Failed to send email to: alexvlg34@gmail.com
Traceback (most recent call last):
  File "/home/airflow/.local/lib/python3.10/site-packages/airflow/models/taskinstance.py", line 2479, in _run_raw_task
    self._execute_task_with_callbacks(context, test_mode, session=session)
  File "/home/airflow/.local/lib/python3.10/site-packages/airflow/models/taskinstance.py", line 2676, in _execute_task_with_callbacks
    result = self._execute_task(context, task_orig)
  File "/home/airflow/.local/lib/python3.10/site-packages/airflow/models/taskinstance.py", line 2701, in _execute_task
    return _execute_task(self, context, task_orig)
  File "/home/airflow/.local/lib/python3.10/site-packages/airflow/models/taskinstance.py", line 465, in _execute_task
    result = _execute_callable(context=context, **execute_callable_kwargs)
  File "/home/airflow/.local/lib/python3.10/site-packages/airflow/models/taskinstance.py", line 432, in _execute_callable
    return execute_callable(context=context, **execute_callable_kwargs)
  File "/home/airflow/.local/lib/python3.10/site-packages/airflow/models/baseoperator.py", line 401, in wrapper
    return func(self, *args, **kwargs)
  File "/home/airflow/.local/lib/python3.10/site-packages/airflow/operators/python.py", line 235, in execute
    return_value = self.execute_callable()
  File "/home/airflow/.local/lib/python3.10/site-packages/airflow/operators/python.py", line 252, in execute_callable
    return self.python_callable(*self.op_args, **self.op_kwargs)
  File "/opt/airflow/dags/airflow/dags/.ipynb_checkpoints/hw1-checkpoint.py", line 113, in prepare_data
    data = s3_download_file(kwargs['model_name'], 'dataset')
  File "/opt/airflow/dags/airflow/dags/.ipynb_checkpoints/hw1-checkpoint.py", line 78, in s3_download_file
    buffer = io.BytesIO(s3_object.get()['Body'].read())
AttributeError: 'str' object has no attribute 'get'

During handling of the above exception, another exception occurred:

Traceback (most recent call last):
  File "/home/airflow/.local/lib/python3.10/site-packages/airflow/models/taskinstance.py", line 1063, in _email_alert
    send_email(task.email, subject, html_content)
  File "/home/airflow/.local/lib/python3.10/site-packages/airflow/utils/email.py", line 80, in send_email
    return backend(
  File "/home/airflow/.local/lib/python3.10/site-packages/airflow/utils/email.py", line 154, in send_email_smtp
    send_mime_email(e_from=mail_from, e_to=recipients, mime_msg=msg, conn_id=conn_id, dryrun=dryrun)
  File "/home/airflow/.local/lib/python3.10/site-packages/airflow/utils/email.py", line 273, in send_mime_email
    smtp_conn = _get_smtp_connection(smtp_host, smtp_port, smtp_timeout, smtp_ssl)
  File "/home/airflow/.local/lib/python3.10/site-packages/airflow/utils/email.py", line 317, in _get_smtp_connection
    return smtplib.SMTP(host=host, port=port, timeout=timeout)
  File "/usr/local/lib/python3.10/smtplib.py", line 255, in __init__
    (code, msg) = self.connect(host, port)
  File "/usr/local/lib/python3.10/smtplib.py", line 341, in connect
    self.sock = self._get_socket(host, port, self.timeout)
  File "/usr/local/lib/python3.10/smtplib.py", line 312, in _get_socket
    return socket.create_connection((host, port), timeout,
  File "/usr/local/lib/python3.10/socket.py", line 845, in create_connection
    raise err
  File "/usr/local/lib/python3.10/socket.py", line 833, in create_connection
    sock.connect(sa)
ConnectionRefusedError: [Errno 111] Connection refused

During handling of the above exception, another exception occurred:

Traceback (most recent call last):
  File "/home/airflow/.local/lib/python3.10/site-packages/airflow/models/taskinstance.py", line 877, in _handle_failure
    task_instance.email_alert(error, failure_context["task"])
  File "/home/airflow/.local/lib/python3.10/site-packages/airflow/models/taskinstance.py", line 3163, in email_alert
    _email_alert(task_instance=self, exception=exception, task=task)
  File "/home/airflow/.local/lib/python3.10/site-packages/airflow/models/taskinstance.py", line 1065, in _email_alert
    send_email(task.email, subject, html_content_err)
  File "/home/airflow/.local/lib/python3.10/site-packages/airflow/utils/email.py", line 80, in send_email
    return backend(
  File "/home/airflow/.local/lib/python3.10/site-packages/airflow/utils/email.py", line 154, in send_email_smtp
    send_mime_email(e_from=mail_from, e_to=recipients, mime_msg=msg, conn_id=conn_id, dryrun=dryrun)
  File "/home/airflow/.local/lib/python3.10/site-packages/airflow/utils/email.py", line 273, in send_mime_email
    smtp_conn = _get_smtp_connection(smtp_host, smtp_port, smtp_timeout, smtp_ssl)
  File "/home/airflow/.local/lib/python3.10/site-packages/airflow/utils/email.py", line 317, in _get_smtp_connection
    return smtplib.SMTP(host=host, port=port, timeout=timeout)
  File "/usr/local/lib/python3.10/smtplib.py", line 255, in __init__
    (code, msg) = self.connect(host, port)
  File "/usr/local/lib/python3.10/smtplib.py", line 341, in connect
    self.sock = self._get_socket(host, port, self.timeout)
  File "/usr/local/lib/python3.10/smtplib.py", line 312, in _get_socket
    return socket.create_connection((host, port), timeout,
  File "/usr/local/lib/python3.10/socket.py", line 845, in create_connection
    raise err
  File "/usr/local/lib/python3.10/socket.py", line 833, in create_connection
    sock.connect(sa)
ConnectionRefusedError: [Errno 111] Connection refused
[2024-09-24T17:42:13.821+0000] {standard_task_runner.py:110} ERROR - Failed to execute job 375 for task prepare_data ('str' object has no attribute 'get'; 28877)
[2024-09-24T17:42:13.853+0000] {local_task_job_runner.py:243} INFO - Task exited with return code 1
[2024-09-24T17:42:13.872+0000] {taskinstance.py:3503} INFO - 0 downstream tasks scheduled from follow-on schedule check
[2024-09-24T17:42:13.878+0000] {local_task_job_runner.py:222} INFO - ::endgroup::
