[2024-10-04T12:02:56.470+0000] {local_task_job_runner.py:120} INFO - ::group::Pre task execution logs
[2024-10-04T12:02:56.492+0000] {taskinstance.py:2076} INFO - Dependencies all met for dep_context=non-requeueable deps ti=<TaskInstance: Alex_Trigolos.training_gbc_model_tasks manual__2024-10-04T12:02:41.902399+00:00 [queued]>
[2024-10-04T12:02:56.503+0000] {taskinstance.py:2076} INFO - Dependencies all met for dep_context=requeueable deps ti=<TaskInstance: Alex_Trigolos.training_gbc_model_tasks manual__2024-10-04T12:02:41.902399+00:00 [queued]>
[2024-10-04T12:02:56.505+0000] {taskinstance.py:2306} INFO - Starting attempt 1 of 1
[2024-10-04T12:02:56.523+0000] {taskinstance.py:2330} INFO - Executing <Task(PythonOperator): training_gbc_model_tasks> on 2024-10-04 12:02:41.902399+00:00
[2024-10-04T12:02:56.535+0000] {standard_task_runner.py:64} INFO - Started process 57337 to run task
[2024-10-04T12:02:56.538+0000] {standard_task_runner.py:90} INFO - Running: ['***', 'tasks', 'run', 'Alex_Trigolos', 'training_gbc_model_tasks', 'manual__2024-10-04T12:02:41.902399+00:00', '--job-id', '820', '--raw', '--subdir', 'DAGS_FOLDER/***/dags/.ipynb_checkpoints/project-checkpoint.py', '--cfg-path', '/tmp/tmp4id3cckp']
[2024-10-04T12:02:56.542+0000] {standard_task_runner.py:91} INFO - Job 820: Subtask training_gbc_model_tasks
[2024-10-04T12:02:56.601+0000] {task_command.py:426} INFO - Running <TaskInstance: Alex_Trigolos.training_gbc_model_tasks manual__2024-10-04T12:02:41.902399+00:00 [running]> on host 4b5f1410d111
[2024-10-04T12:02:56.722+0000] {taskinstance.py:2648} INFO - Exporting env vars: AIRFLOW_CTX_DAG_EMAIL='alexvlg34@gmail.com' AIRFLOW_CTX_DAG_OWNER='Alex Trigolos' AIRFLOW_CTX_DAG_ID='Alex_Trigolos' AIRFLOW_CTX_TASK_ID='training_gbc_model_tasks' AIRFLOW_CTX_EXECUTION_DATE='2024-10-04T12:02:41.902399+00:00' AIRFLOW_CTX_TRY_NUMBER='1' AIRFLOW_CTX_DAG_RUN_ID='manual__2024-10-04T12:02:41.902399+00:00'
[2024-10-04T12:02:56.724+0000] {taskinstance.py:430} INFO - ::endgroup::
[2024-10-04T12:02:56.740+0000] {project-checkpoint.py:166} INFO - Train model...
[2024-10-04T12:02:56.770+0000] {s3.py:1422} INFO - Downloading source S3 file from Bucket testmlops with path AlexTrigolos/project/datasets/X_train.pkl
[2024-10-04T12:02:56.785+0000] {base.py:84} INFO - Using connection ID 's3_connection' for task execution.
[2024-10-04T12:02:56.787+0000] {connection_wrapper.py:388} INFO - AWS Connection (conn_id='s3_connection', conn_type='aws') credentials retrieved from login and password.
[2024-10-04T12:02:57.021+0000] {project-checkpoint.py:93} INFO - /tmp/***_tmp_f4ep8emu
[2024-10-04T12:02:57.029+0000] {s3.py:1422} INFO - Downloading source S3 file from Bucket testmlops with path AlexTrigolos/project/datasets/X_val.pkl
[2024-10-04T12:02:57.038+0000] {base.py:84} INFO - Using connection ID 's3_connection' for task execution.
[2024-10-04T12:02:57.039+0000] {connection_wrapper.py:388} INFO - AWS Connection (conn_id='s3_connection', conn_type='aws') credentials retrieved from login and password.
[2024-10-04T12:02:57.259+0000] {project-checkpoint.py:93} INFO - /tmp/***_tmp_vnlkda35
[2024-10-04T12:02:57.262+0000] {s3.py:1422} INFO - Downloading source S3 file from Bucket testmlops with path AlexTrigolos/project/datasets/X_test.pkl
[2024-10-04T12:02:57.271+0000] {base.py:84} INFO - Using connection ID 's3_connection' for task execution.
[2024-10-04T12:02:57.272+0000] {connection_wrapper.py:388} INFO - AWS Connection (conn_id='s3_connection', conn_type='aws') credentials retrieved from login and password.
[2024-10-04T12:02:57.857+0000] {project-checkpoint.py:93} INFO - /tmp/***_tmp_6fhhhvqc
[2024-10-04T12:02:57.861+0000] {s3.py:1422} INFO - Downloading source S3 file from Bucket testmlops with path AlexTrigolos/project/datasets/y_train.pkl
[2024-10-04T12:02:57.871+0000] {base.py:84} INFO - Using connection ID 's3_connection' for task execution.
[2024-10-04T12:02:57.873+0000] {connection_wrapper.py:388} INFO - AWS Connection (conn_id='s3_connection', conn_type='aws') credentials retrieved from login and password.
[2024-10-04T12:02:58.094+0000] {project-checkpoint.py:93} INFO - /tmp/***_tmp_wdx9_m8x
[2024-10-04T12:02:58.098+0000] {s3.py:1422} INFO - Downloading source S3 file from Bucket testmlops with path AlexTrigolos/project/datasets/y_val.pkl
[2024-10-04T12:02:58.108+0000] {base.py:84} INFO - Using connection ID 's3_connection' for task execution.
[2024-10-04T12:02:58.109+0000] {connection_wrapper.py:388} INFO - AWS Connection (conn_id='s3_connection', conn_type='aws') credentials retrieved from login and password.
[2024-10-04T12:02:58.311+0000] {project-checkpoint.py:93} INFO - /tmp/***_tmp_hpsx9ocg
[2024-10-04T12:02:58.314+0000] {s3.py:1422} INFO - Downloading source S3 file from Bucket testmlops with path AlexTrigolos/project/datasets/y_test.pkl
[2024-10-04T12:02:58.324+0000] {base.py:84} INFO - Using connection ID 's3_connection' for task execution.
[2024-10-04T12:02:58.326+0000] {connection_wrapper.py:388} INFO - AWS Connection (conn_id='s3_connection', conn_type='aws') credentials retrieved from login and password.
[2024-10-04T12:02:58.535+0000] {project-checkpoint.py:93} INFO - /tmp/***_tmp_9uk14akz
[2024-10-04T12:02:58.541+0000] {taskinstance.py:441} INFO - ::group::Post task execution logs
[2024-10-04T12:02:58.542+0000] {taskinstance.py:2905} ERROR - Task failed with exception
Traceback (most recent call last):
  File "/home/airflow/.local/lib/python3.10/site-packages/airflow/models/taskinstance.py", line 465, in _execute_task
    result = _execute_callable(context=context, **execute_callable_kwargs)
  File "/home/airflow/.local/lib/python3.10/site-packages/airflow/models/taskinstance.py", line 432, in _execute_callable
    return execute_callable(context=context, **execute_callable_kwargs)
  File "/home/airflow/.local/lib/python3.10/site-packages/airflow/models/baseoperator.py", line 401, in wrapper
    return func(self, *args, **kwargs)
  File "/home/airflow/.local/lib/python3.10/site-packages/airflow/operators/python.py", line 235, in execute
    return_value = self.execute_callable()
  File "/home/airflow/.local/lib/python3.10/site-packages/airflow/operators/python.py", line 252, in execute_callable
    return self.python_callable(*self.op_args, **self.op_kwargs)
  File "/opt/airflow/dags/airflow/dags/.ipynb_checkpoints/project-checkpoint.py", line 184, in train_model
    with mlflow.start_run(parent_run_id=parent_run_id, run_name=model_name, experiment_id=exp_id, nested=True) as child_run:
  File "/home/airflow/.local/lib/python3.10/site-packages/mlflow/tracking/fluent.py", line 386, in start_run
    parent_run_obj = client.get_run(parent_run_id)
  File "/home/airflow/.local/lib/python3.10/site-packages/mlflow/tracking/client.py", line 226, in get_run
    return self._tracking_client.get_run(run_id)
  File "/home/airflow/.local/lib/python3.10/site-packages/mlflow/tracking/_tracking_service/client.py", line 104, in get_run
    return self.store.get_run(run_id)
  File "/home/airflow/.local/lib/python3.10/site-packages/mlflow/store/tracking/file_store.py", line 678, in get_run
    run_info = self._get_run_info(run_id)
  File "/home/airflow/.local/lib/python3.10/site-packages/mlflow/store/tracking/file_store.py", line 702, in _get_run_info
    raise MlflowException(
mlflow.exceptions.MlflowException: Run '43d27384e744485e9e57c1f9eb799202' not found
[2024-10-04T12:02:58.563+0000] {taskinstance.py:1206} INFO - Marking task as FAILED. dag_id=Alex_Trigolos, task_id=training_gbc_model_tasks, run_id=manual__2024-10-04T12:02:41.902399+00:00, execution_date=20241004T120241, start_date=20241004T120256, end_date=20241004T120258
[2024-10-04T12:02:58.585+0000] {logging_mixin.py:188} WARNING - /home/***/.local/lib/python3.10/site-packages/***/utils/email.py:154 RemovedInAirflow3Warning: Fetching SMTP credentials from configuration variables will be deprecated in a future release. Please set credentials using a connection instead.
[2024-10-04T12:02:58.586+0000] {configuration.py:1053} WARNING - section/key [smtp/smtp_user] not found in config
[2024-10-04T12:02:58.587+0000] {email.py:271} INFO - Email alerting: attempt 1
[2024-10-04T12:02:58.597+0000] {configuration.py:1053} WARNING - section/key [smtp/smtp_user] not found in config
[2024-10-04T12:02:58.598+0000] {email.py:271} INFO - Email alerting: attempt 1
[2024-10-04T12:02:58.599+0000] {taskinstance.py:879} ERROR - Failed to send email to: alexvlg34@gmail.com
Traceback (most recent call last):
  File "/home/airflow/.local/lib/python3.10/site-packages/airflow/models/taskinstance.py", line 2479, in _run_raw_task
    self._execute_task_with_callbacks(context, test_mode, session=session)
  File "/home/airflow/.local/lib/python3.10/site-packages/airflow/models/taskinstance.py", line 2676, in _execute_task_with_callbacks
    result = self._execute_task(context, task_orig)
  File "/home/airflow/.local/lib/python3.10/site-packages/airflow/models/taskinstance.py", line 2701, in _execute_task
    return _execute_task(self, context, task_orig)
  File "/home/airflow/.local/lib/python3.10/site-packages/airflow/models/taskinstance.py", line 465, in _execute_task
    result = _execute_callable(context=context, **execute_callable_kwargs)
  File "/home/airflow/.local/lib/python3.10/site-packages/airflow/models/taskinstance.py", line 432, in _execute_callable
    return execute_callable(context=context, **execute_callable_kwargs)
  File "/home/airflow/.local/lib/python3.10/site-packages/airflow/models/baseoperator.py", line 401, in wrapper
    return func(self, *args, **kwargs)
  File "/home/airflow/.local/lib/python3.10/site-packages/airflow/operators/python.py", line 235, in execute
    return_value = self.execute_callable()
  File "/home/airflow/.local/lib/python3.10/site-packages/airflow/operators/python.py", line 252, in execute_callable
    return self.python_callable(*self.op_args, **self.op_kwargs)
  File "/opt/airflow/dags/airflow/dags/.ipynb_checkpoints/project-checkpoint.py", line 184, in train_model
    with mlflow.start_run(parent_run_id=parent_run_id, run_name=model_name, experiment_id=exp_id, nested=True) as child_run:
  File "/home/airflow/.local/lib/python3.10/site-packages/mlflow/tracking/fluent.py", line 386, in start_run
    parent_run_obj = client.get_run(parent_run_id)
  File "/home/airflow/.local/lib/python3.10/site-packages/mlflow/tracking/client.py", line 226, in get_run
    return self._tracking_client.get_run(run_id)
  File "/home/airflow/.local/lib/python3.10/site-packages/mlflow/tracking/_tracking_service/client.py", line 104, in get_run
    return self.store.get_run(run_id)
  File "/home/airflow/.local/lib/python3.10/site-packages/mlflow/store/tracking/file_store.py", line 678, in get_run
    run_info = self._get_run_info(run_id)
  File "/home/airflow/.local/lib/python3.10/site-packages/mlflow/store/tracking/file_store.py", line 702, in _get_run_info
    raise MlflowException(
mlflow.exceptions.MlflowException: Run '43d27384e744485e9e57c1f9eb799202' not found

During handling of the above exception, another exception occurred:

Traceback (most recent call last):
  File "/home/airflow/.local/lib/python3.10/site-packages/airflow/models/taskinstance.py", line 1063, in _email_alert
    send_email(task.email, subject, html_content)
  File "/home/airflow/.local/lib/python3.10/site-packages/airflow/utils/email.py", line 80, in send_email
    return backend(
  File "/home/airflow/.local/lib/python3.10/site-packages/airflow/utils/email.py", line 154, in send_email_smtp
    send_mime_email(e_from=mail_from, e_to=recipients, mime_msg=msg, conn_id=conn_id, dryrun=dryrun)
  File "/home/airflow/.local/lib/python3.10/site-packages/airflow/utils/email.py", line 273, in send_mime_email
    smtp_conn = _get_smtp_connection(smtp_host, smtp_port, smtp_timeout, smtp_ssl)
  File "/home/airflow/.local/lib/python3.10/site-packages/airflow/utils/email.py", line 317, in _get_smtp_connection
    return smtplib.SMTP(host=host, port=port, timeout=timeout)
  File "/usr/local/lib/python3.10/smtplib.py", line 255, in __init__
    (code, msg) = self.connect(host, port)
  File "/usr/local/lib/python3.10/smtplib.py", line 341, in connect
    self.sock = self._get_socket(host, port, self.timeout)
  File "/usr/local/lib/python3.10/smtplib.py", line 312, in _get_socket
    return socket.create_connection((host, port), timeout,
  File "/usr/local/lib/python3.10/socket.py", line 845, in create_connection
    raise err
  File "/usr/local/lib/python3.10/socket.py", line 833, in create_connection
    sock.connect(sa)
ConnectionRefusedError: [Errno 111] Connection refused

During handling of the above exception, another exception occurred:

Traceback (most recent call last):
  File "/home/airflow/.local/lib/python3.10/site-packages/airflow/models/taskinstance.py", line 877, in _handle_failure
    task_instance.email_alert(error, failure_context["task"])
  File "/home/airflow/.local/lib/python3.10/site-packages/airflow/models/taskinstance.py", line 3163, in email_alert
    _email_alert(task_instance=self, exception=exception, task=task)
  File "/home/airflow/.local/lib/python3.10/site-packages/airflow/models/taskinstance.py", line 1065, in _email_alert
    send_email(task.email, subject, html_content_err)
  File "/home/airflow/.local/lib/python3.10/site-packages/airflow/utils/email.py", line 80, in send_email
    return backend(
  File "/home/airflow/.local/lib/python3.10/site-packages/airflow/utils/email.py", line 154, in send_email_smtp
    send_mime_email(e_from=mail_from, e_to=recipients, mime_msg=msg, conn_id=conn_id, dryrun=dryrun)
  File "/home/airflow/.local/lib/python3.10/site-packages/airflow/utils/email.py", line 273, in send_mime_email
    smtp_conn = _get_smtp_connection(smtp_host, smtp_port, smtp_timeout, smtp_ssl)
  File "/home/airflow/.local/lib/python3.10/site-packages/airflow/utils/email.py", line 317, in _get_smtp_connection
    return smtplib.SMTP(host=host, port=port, timeout=timeout)
  File "/usr/local/lib/python3.10/smtplib.py", line 255, in __init__
    (code, msg) = self.connect(host, port)
  File "/usr/local/lib/python3.10/smtplib.py", line 341, in connect
    self.sock = self._get_socket(host, port, self.timeout)
  File "/usr/local/lib/python3.10/smtplib.py", line 312, in _get_socket
    return socket.create_connection((host, port), timeout,
  File "/usr/local/lib/python3.10/socket.py", line 845, in create_connection
    raise err
  File "/usr/local/lib/python3.10/socket.py", line 833, in create_connection
    sock.connect(sa)
ConnectionRefusedError: [Errno 111] Connection refused
[2024-10-04T12:02:58.619+0000] {standard_task_runner.py:110} ERROR - Failed to execute job 820 for task training_gbc_model_tasks (Run '43d27384e744485e9e57c1f9eb799202' not found; 57337)
[2024-10-04T12:02:58.648+0000] {local_task_job_runner.py:243} INFO - Task exited with return code 1
[2024-10-04T12:02:58.670+0000] {taskinstance.py:3503} INFO - 0 downstream tasks scheduled from follow-on schedule check
[2024-10-04T12:02:58.672+0000] {local_task_job_runner.py:222} INFO - ::endgroup::
