[2024-10-04T12:21:19.647+0000] {local_task_job_runner.py:120} INFO - ::group::Pre task execution logs
[2024-10-04T12:21:19.678+0000] {taskinstance.py:2076} INFO - Dependencies all met for dep_context=non-requeueable deps ti=<TaskInstance: Alex_Trigolos.training_dtc_model_tasks manual__2024-10-04T12:21:01.881382+00:00 [queued]>
[2024-10-04T12:21:19.690+0000] {taskinstance.py:2076} INFO - Dependencies all met for dep_context=requeueable deps ti=<TaskInstance: Alex_Trigolos.training_dtc_model_tasks manual__2024-10-04T12:21:01.881382+00:00 [queued]>
[2024-10-04T12:21:19.692+0000] {taskinstance.py:2306} INFO - Starting attempt 1 of 1
[2024-10-04T12:21:19.711+0000] {taskinstance.py:2330} INFO - Executing <Task(PythonOperator): training_dtc_model_tasks> on 2024-10-04 12:21:01.881382+00:00
[2024-10-04T12:21:19.726+0000] {standard_task_runner.py:64} INFO - Started process 68078 to run task
[2024-10-04T12:21:19.731+0000] {standard_task_runner.py:90} INFO - Running: ['***', 'tasks', 'run', 'Alex_Trigolos', 'training_dtc_model_tasks', 'manual__2024-10-04T12:21:01.881382+00:00', '--job-id', '839', '--raw', '--subdir', 'DAGS_FOLDER/***/dags/project.py', '--cfg-path', '/tmp/tmptaf736ik']
[2024-10-04T12:21:19.734+0000] {standard_task_runner.py:91} INFO - Job 839: Subtask training_dtc_model_tasks
[2024-10-04T12:21:19.808+0000] {task_command.py:426} INFO - Running <TaskInstance: Alex_Trigolos.training_dtc_model_tasks manual__2024-10-04T12:21:01.881382+00:00 [running]> on host 4b5f1410d111
[2024-10-04T12:21:19.960+0000] {taskinstance.py:2648} INFO - Exporting env vars: AIRFLOW_CTX_DAG_EMAIL='alexvlg34@gmail.com' AIRFLOW_CTX_DAG_OWNER='Alex Trigolos' AIRFLOW_CTX_DAG_ID='Alex_Trigolos' AIRFLOW_CTX_TASK_ID='training_dtc_model_tasks' AIRFLOW_CTX_EXECUTION_DATE='2024-10-04T12:21:01.881382+00:00' AIRFLOW_CTX_TRY_NUMBER='1' AIRFLOW_CTX_DAG_RUN_ID='manual__2024-10-04T12:21:01.881382+00:00'
[2024-10-04T12:21:19.962+0000] {taskinstance.py:430} INFO - ::endgroup::
[2024-10-04T12:21:19.986+0000] {project.py:166} INFO - Train model...
[2024-10-04T12:21:20.006+0000] {project.py:169} INFO - 522034352521652390
[2024-10-04T12:21:20.029+0000] {project.py:171} INFO - cff955a8d1054daf97d5d4af1c8cb133
[2024-10-04T12:21:20.031+0000] {s3.py:1422} INFO - Downloading source S3 file from Bucket testmlops with path AlexTrigolos/project/datasets/X_train.pkl
[2024-10-04T12:21:20.048+0000] {base.py:84} INFO - Using connection ID 's3_connection' for task execution.
[2024-10-04T12:21:20.049+0000] {connection_wrapper.py:388} INFO - AWS Connection (conn_id='s3_connection', conn_type='aws') credentials retrieved from login and password.
[2024-10-04T12:21:20.343+0000] {project.py:93} INFO - /tmp/***_tmp_3a1pp75m
[2024-10-04T12:21:20.349+0000] {s3.py:1422} INFO - Downloading source S3 file from Bucket testmlops with path AlexTrigolos/project/datasets/X_val.pkl
[2024-10-04T12:21:20.365+0000] {base.py:84} INFO - Using connection ID 's3_connection' for task execution.
[2024-10-04T12:21:20.367+0000] {connection_wrapper.py:388} INFO - AWS Connection (conn_id='s3_connection', conn_type='aws') credentials retrieved from login and password.
[2024-10-04T12:21:20.656+0000] {project.py:93} INFO - /tmp/***_tmp_unl4l0ce
[2024-10-04T12:21:20.659+0000] {s3.py:1422} INFO - Downloading source S3 file from Bucket testmlops with path AlexTrigolos/project/datasets/X_test.pkl
[2024-10-04T12:21:20.670+0000] {base.py:84} INFO - Using connection ID 's3_connection' for task execution.
[2024-10-04T12:21:20.672+0000] {connection_wrapper.py:388} INFO - AWS Connection (conn_id='s3_connection', conn_type='aws') credentials retrieved from login and password.
[2024-10-04T12:21:21.255+0000] {project.py:93} INFO - /tmp/***_tmp_96idq6ls
[2024-10-04T12:21:21.259+0000] {s3.py:1422} INFO - Downloading source S3 file from Bucket testmlops with path AlexTrigolos/project/datasets/y_train.pkl
[2024-10-04T12:21:21.271+0000] {base.py:84} INFO - Using connection ID 's3_connection' for task execution.
[2024-10-04T12:21:21.272+0000] {connection_wrapper.py:388} INFO - AWS Connection (conn_id='s3_connection', conn_type='aws') credentials retrieved from login and password.
[2024-10-04T12:21:21.526+0000] {project.py:93} INFO - /tmp/***_tmp__0nbup9i
[2024-10-04T12:21:21.529+0000] {s3.py:1422} INFO - Downloading source S3 file from Bucket testmlops with path AlexTrigolos/project/datasets/y_val.pkl
[2024-10-04T12:21:21.540+0000] {base.py:84} INFO - Using connection ID 's3_connection' for task execution.
[2024-10-04T12:21:21.544+0000] {connection_wrapper.py:388} INFO - AWS Connection (conn_id='s3_connection', conn_type='aws') credentials retrieved from login and password.
[2024-10-04T12:21:21.783+0000] {project.py:93} INFO - /tmp/***_tmp_42yw0byk
[2024-10-04T12:21:21.788+0000] {s3.py:1422} INFO - Downloading source S3 file from Bucket testmlops with path AlexTrigolos/project/datasets/y_test.pkl
[2024-10-04T12:21:21.799+0000] {base.py:84} INFO - Using connection ID 's3_connection' for task execution.
[2024-10-04T12:21:21.800+0000] {connection_wrapper.py:388} INFO - AWS Connection (conn_id='s3_connection', conn_type='aws') credentials retrieved from login and password.
[2024-10-04T12:21:22.029+0000] {project.py:93} INFO - /tmp/***_tmp_qqid__my
[2024-10-04T12:21:22.035+0000] {taskinstance.py:441} INFO - ::group::Post task execution logs
[2024-10-04T12:21:22.036+0000] {taskinstance.py:2905} ERROR - Task failed with exception
Traceback (most recent call last):
  File "/home/airflow/.local/lib/python3.10/site-packages/airflow/models/taskinstance.py", line 465, in _execute_task
    result = _execute_callable(context=context, **execute_callable_kwargs)
  File "/home/airflow/.local/lib/python3.10/site-packages/airflow/models/taskinstance.py", line 432, in _execute_callable
    return execute_callable(context=context, **execute_callable_kwargs)
  File "/home/airflow/.local/lib/python3.10/site-packages/airflow/models/baseoperator.py", line 401, in wrapper
    return func(self, *args, **kwargs)
  File "/home/airflow/.local/lib/python3.10/site-packages/airflow/operators/python.py", line 235, in execute
    return_value = self.execute_callable()
  File "/home/airflow/.local/lib/python3.10/site-packages/airflow/operators/python.py", line 252, in execute_callable
    return self.python_callable(*self.op_args, **self.op_kwargs)
  File "/opt/airflow/dags/airflow/dags/project.py", line 186, in train_model
    with mlflow.start_run(parent_run_id=parent_run_id, run_name=model_name, experiment_id=exp_id, nested=True) as child_run:
  File "/home/airflow/.local/lib/python3.10/site-packages/mlflow/tracking/fluent.py", line 386, in start_run
    parent_run_obj = client.get_run(parent_run_id)
  File "/home/airflow/.local/lib/python3.10/site-packages/mlflow/tracking/client.py", line 226, in get_run
    return self._tracking_client.get_run(run_id)
  File "/home/airflow/.local/lib/python3.10/site-packages/mlflow/tracking/_tracking_service/client.py", line 104, in get_run
    return self.store.get_run(run_id)
  File "/home/airflow/.local/lib/python3.10/site-packages/mlflow/store/tracking/file_store.py", line 678, in get_run
    run_info = self._get_run_info(run_id)
  File "/home/airflow/.local/lib/python3.10/site-packages/mlflow/store/tracking/file_store.py", line 702, in _get_run_info
    raise MlflowException(
mlflow.exceptions.MlflowException: Run 'cff955a8d1054daf97d5d4af1c8cb133' not found
[2024-10-04T12:21:22.054+0000] {taskinstance.py:1206} INFO - Marking task as FAILED. dag_id=Alex_Trigolos, task_id=training_dtc_model_tasks, run_id=manual__2024-10-04T12:21:01.881382+00:00, execution_date=20241004T122101, start_date=20241004T122119, end_date=20241004T122122
[2024-10-04T12:21:22.074+0000] {logging_mixin.py:188} WARNING - /home/***/.local/lib/python3.10/site-packages/***/utils/email.py:154 RemovedInAirflow3Warning: Fetching SMTP credentials from configuration variables will be deprecated in a future release. Please set credentials using a connection instead.
[2024-10-04T12:21:22.075+0000] {configuration.py:1053} WARNING - section/key [smtp/smtp_user] not found in config
[2024-10-04T12:21:22.075+0000] {email.py:271} INFO - Email alerting: attempt 1
[2024-10-04T12:21:22.084+0000] {configuration.py:1053} WARNING - section/key [smtp/smtp_user] not found in config
[2024-10-04T12:21:22.085+0000] {email.py:271} INFO - Email alerting: attempt 1
[2024-10-04T12:21:22.086+0000] {taskinstance.py:879} ERROR - Failed to send email to: alexvlg34@gmail.com
Traceback (most recent call last):
  File "/home/airflow/.local/lib/python3.10/site-packages/airflow/models/taskinstance.py", line 2479, in _run_raw_task
    self._execute_task_with_callbacks(context, test_mode, session=session)
  File "/home/airflow/.local/lib/python3.10/site-packages/airflow/models/taskinstance.py", line 2676, in _execute_task_with_callbacks
    result = self._execute_task(context, task_orig)
  File "/home/airflow/.local/lib/python3.10/site-packages/airflow/models/taskinstance.py", line 2701, in _execute_task
    return _execute_task(self, context, task_orig)
  File "/home/airflow/.local/lib/python3.10/site-packages/airflow/models/taskinstance.py", line 465, in _execute_task
    result = _execute_callable(context=context, **execute_callable_kwargs)
  File "/home/airflow/.local/lib/python3.10/site-packages/airflow/models/taskinstance.py", line 432, in _execute_callable
    return execute_callable(context=context, **execute_callable_kwargs)
  File "/home/airflow/.local/lib/python3.10/site-packages/airflow/models/baseoperator.py", line 401, in wrapper
    return func(self, *args, **kwargs)
  File "/home/airflow/.local/lib/python3.10/site-packages/airflow/operators/python.py", line 235, in execute
    return_value = self.execute_callable()
  File "/home/airflow/.local/lib/python3.10/site-packages/airflow/operators/python.py", line 252, in execute_callable
    return self.python_callable(*self.op_args, **self.op_kwargs)
  File "/opt/airflow/dags/airflow/dags/project.py", line 186, in train_model
    with mlflow.start_run(parent_run_id=parent_run_id, run_name=model_name, experiment_id=exp_id, nested=True) as child_run:
  File "/home/airflow/.local/lib/python3.10/site-packages/mlflow/tracking/fluent.py", line 386, in start_run
    parent_run_obj = client.get_run(parent_run_id)
  File "/home/airflow/.local/lib/python3.10/site-packages/mlflow/tracking/client.py", line 226, in get_run
    return self._tracking_client.get_run(run_id)
  File "/home/airflow/.local/lib/python3.10/site-packages/mlflow/tracking/_tracking_service/client.py", line 104, in get_run
    return self.store.get_run(run_id)
  File "/home/airflow/.local/lib/python3.10/site-packages/mlflow/store/tracking/file_store.py", line 678, in get_run
    run_info = self._get_run_info(run_id)
  File "/home/airflow/.local/lib/python3.10/site-packages/mlflow/store/tracking/file_store.py", line 702, in _get_run_info
    raise MlflowException(
mlflow.exceptions.MlflowException: Run 'cff955a8d1054daf97d5d4af1c8cb133' not found

During handling of the above exception, another exception occurred:

Traceback (most recent call last):
  File "/home/airflow/.local/lib/python3.10/site-packages/airflow/models/taskinstance.py", line 1063, in _email_alert
    send_email(task.email, subject, html_content)
  File "/home/airflow/.local/lib/python3.10/site-packages/airflow/utils/email.py", line 80, in send_email
    return backend(
  File "/home/airflow/.local/lib/python3.10/site-packages/airflow/utils/email.py", line 154, in send_email_smtp
    send_mime_email(e_from=mail_from, e_to=recipients, mime_msg=msg, conn_id=conn_id, dryrun=dryrun)
  File "/home/airflow/.local/lib/python3.10/site-packages/airflow/utils/email.py", line 273, in send_mime_email
    smtp_conn = _get_smtp_connection(smtp_host, smtp_port, smtp_timeout, smtp_ssl)
  File "/home/airflow/.local/lib/python3.10/site-packages/airflow/utils/email.py", line 317, in _get_smtp_connection
    return smtplib.SMTP(host=host, port=port, timeout=timeout)
  File "/usr/local/lib/python3.10/smtplib.py", line 255, in __init__
    (code, msg) = self.connect(host, port)
  File "/usr/local/lib/python3.10/smtplib.py", line 341, in connect
    self.sock = self._get_socket(host, port, self.timeout)
  File "/usr/local/lib/python3.10/smtplib.py", line 312, in _get_socket
    return socket.create_connection((host, port), timeout,
  File "/usr/local/lib/python3.10/socket.py", line 845, in create_connection
    raise err
  File "/usr/local/lib/python3.10/socket.py", line 833, in create_connection
    sock.connect(sa)
ConnectionRefusedError: [Errno 111] Connection refused

During handling of the above exception, another exception occurred:

Traceback (most recent call last):
  File "/home/airflow/.local/lib/python3.10/site-packages/airflow/models/taskinstance.py", line 877, in _handle_failure
    task_instance.email_alert(error, failure_context["task"])
  File "/home/airflow/.local/lib/python3.10/site-packages/airflow/models/taskinstance.py", line 3163, in email_alert
    _email_alert(task_instance=self, exception=exception, task=task)
  File "/home/airflow/.local/lib/python3.10/site-packages/airflow/models/taskinstance.py", line 1065, in _email_alert
    send_email(task.email, subject, html_content_err)
  File "/home/airflow/.local/lib/python3.10/site-packages/airflow/utils/email.py", line 80, in send_email
    return backend(
  File "/home/airflow/.local/lib/python3.10/site-packages/airflow/utils/email.py", line 154, in send_email_smtp
    send_mime_email(e_from=mail_from, e_to=recipients, mime_msg=msg, conn_id=conn_id, dryrun=dryrun)
  File "/home/airflow/.local/lib/python3.10/site-packages/airflow/utils/email.py", line 273, in send_mime_email
    smtp_conn = _get_smtp_connection(smtp_host, smtp_port, smtp_timeout, smtp_ssl)
  File "/home/airflow/.local/lib/python3.10/site-packages/airflow/utils/email.py", line 317, in _get_smtp_connection
    return smtplib.SMTP(host=host, port=port, timeout=timeout)
  File "/usr/local/lib/python3.10/smtplib.py", line 255, in __init__
    (code, msg) = self.connect(host, port)
  File "/usr/local/lib/python3.10/smtplib.py", line 341, in connect
    self.sock = self._get_socket(host, port, self.timeout)
  File "/usr/local/lib/python3.10/smtplib.py", line 312, in _get_socket
    return socket.create_connection((host, port), timeout,
  File "/usr/local/lib/python3.10/socket.py", line 845, in create_connection
    raise err
  File "/usr/local/lib/python3.10/socket.py", line 833, in create_connection
    sock.connect(sa)
ConnectionRefusedError: [Errno 111] Connection refused
[2024-10-04T12:21:22.103+0000] {standard_task_runner.py:110} ERROR - Failed to execute job 839 for task training_dtc_model_tasks (Run 'cff955a8d1054daf97d5d4af1c8cb133' not found; 68078)
[2024-10-04T12:21:22.159+0000] {local_task_job_runner.py:243} INFO - Task exited with return code 1
[2024-10-04T12:21:22.187+0000] {taskinstance.py:3503} INFO - 0 downstream tasks scheduled from follow-on schedule check
[2024-10-04T12:21:22.192+0000] {local_task_job_runner.py:222} INFO - ::endgroup::
