[2024-10-04T13:53:41.895+0000] {local_task_job_runner.py:120} INFO - ::group::Pre task execution logs
[2024-10-04T13:53:41.906+0000] {taskinstance.py:2076} INFO - Dependencies all met for dep_context=non-requeueable deps ti=<TaskInstance: Alex_Trigolos.task_init manual__2024-10-04T13:53:39.661365+00:00 [queued]>
[2024-10-04T13:53:41.913+0000] {taskinstance.py:2076} INFO - Dependencies all met for dep_context=requeueable deps ti=<TaskInstance: Alex_Trigolos.task_init manual__2024-10-04T13:53:39.661365+00:00 [queued]>
[2024-10-04T13:53:41.914+0000] {taskinstance.py:2306} INFO - Starting attempt 1 of 1
[2024-10-04T13:53:41.924+0000] {taskinstance.py:2330} INFO - Executing <Task(PythonOperator): task_init> on 2024-10-04 13:53:39.661365+00:00
[2024-10-04T13:53:41.933+0000] {standard_task_runner.py:64} INFO - Started process 97497 to run task
[2024-10-04T13:53:41.935+0000] {standard_task_runner.py:90} INFO - Running: ['***', 'tasks', 'run', 'Alex_Trigolos', 'task_init', 'manual__2024-10-04T13:53:39.661365+00:00', '--job-id', '897', '--raw', '--subdir', 'DAGS_FOLDER/***/dags/.ipynb_checkpoints/project-checkpoint.py', '--cfg-path', '/tmp/tmpuh5nvqrk']
[2024-10-04T13:53:41.937+0000] {standard_task_runner.py:91} INFO - Job 897: Subtask task_init
[2024-10-04T13:53:41.969+0000] {task_command.py:426} INFO - Running <TaskInstance: Alex_Trigolos.task_init manual__2024-10-04T13:53:39.661365+00:00 [running]> on host 4b5f1410d111
[2024-10-04T13:53:42.029+0000] {taskinstance.py:2648} INFO - Exporting env vars: AIRFLOW_CTX_DAG_EMAIL='alexvlg34@gmail.com' AIRFLOW_CTX_DAG_OWNER='Alex Trigolos' AIRFLOW_CTX_DAG_ID='Alex_Trigolos' AIRFLOW_CTX_TASK_ID='task_init' AIRFLOW_CTX_EXECUTION_DATE='2024-10-04T13:53:39.661365+00:00' AIRFLOW_CTX_TRY_NUMBER='1' AIRFLOW_CTX_DAG_RUN_ID='manual__2024-10-04T13:53:39.661365+00:00'
[2024-10-04T13:53:42.031+0000] {taskinstance.py:430} INFO - ::endgroup::
[2024-10-04T13:53:42.040+0000] {project-checkpoint.py:101} INFO - Train pipeline started.
[2024-10-04T13:53:42.103+0000] {taskinstance.py:441} INFO - ::group::Post task execution logs
[2024-10-04T13:53:42.104+0000] {taskinstance.py:2905} ERROR - Task failed with exception
Traceback (most recent call last):
  File "/home/airflow/.local/lib/python3.10/site-packages/airflow/models/taskinstance.py", line 465, in _execute_task
    result = _execute_callable(context=context, **execute_callable_kwargs)
  File "/home/airflow/.local/lib/python3.10/site-packages/airflow/models/taskinstance.py", line 432, in _execute_callable
    return execute_callable(context=context, **execute_callable_kwargs)
  File "/home/airflow/.local/lib/python3.10/site-packages/airflow/models/baseoperator.py", line 401, in wrapper
    return func(self, *args, **kwargs)
  File "/home/airflow/.local/lib/python3.10/site-packages/airflow/operators/python.py", line 235, in execute
    return_value = self.execute_callable()
  File "/home/airflow/.local/lib/python3.10/site-packages/airflow/operators/python.py", line 252, in execute_callable
    return self.python_callable(*self.op_args, **self.op_kwargs)
  File "/opt/airflow/dags/airflow/dags/.ipynb_checkpoints/project-checkpoint.py", line 111, in init
    exp_id = mlflow.create_experiment(name="Alex Trigolos project")
  File "/home/airflow/.local/lib/python3.10/site-packages/mlflow/tracking/fluent.py", line 1766, in create_experiment
    return MlflowClient().create_experiment(name, artifact_location, tags)
  File "/home/airflow/.local/lib/python3.10/site-packages/mlflow/tracking/client.py", line 1294, in create_experiment
    return self._tracking_client.create_experiment(name, artifact_location, tags)
  File "/home/airflow/.local/lib/python3.10/site-packages/mlflow/tracking/_tracking_service/client.py", line 501, in create_experiment
    return self.store.create_experiment(
  File "/home/airflow/.local/lib/python3.10/site-packages/mlflow/store/tracking/rest_store.py", line 122, in create_experiment
    response_proto = self._call_endpoint(CreateExperiment, req_body)
  File "/home/airflow/.local/lib/python3.10/site-packages/mlflow/store/tracking/rest_store.py", line 81, in _call_endpoint
    return call_endpoint(self.get_host_creds(), endpoint, method, json_body, response_proto)
  File "/home/airflow/.local/lib/python3.10/site-packages/mlflow/utils/rest_utils.py", line 362, in call_endpoint
    response = verify_rest_response(response, endpoint)
  File "/home/airflow/.local/lib/python3.10/site-packages/mlflow/utils/rest_utils.py", line 232, in verify_rest_response
    raise RestException(json.loads(response.text))
mlflow.exceptions.RestException: RESOURCE_ALREADY_EXISTS: Experiment 'Alex Trigolos project' already exists in deleted state. You can restore the experiment, or permanently delete the experiment from the .trash folder (under tracking server's root folder) in order to use this experiment name again.
[2024-10-04T13:53:42.119+0000] {taskinstance.py:1206} INFO - Marking task as FAILED. dag_id=Alex_Trigolos, task_id=task_init, run_id=manual__2024-10-04T13:53:39.661365+00:00, execution_date=20241004T135339, start_date=20241004T135341, end_date=20241004T135342
[2024-10-04T13:53:42.133+0000] {logging_mixin.py:188} WARNING - /home/***/.local/lib/python3.10/site-packages/***/utils/email.py:154 RemovedInAirflow3Warning: Fetching SMTP credentials from configuration variables will be deprecated in a future release. Please set credentials using a connection instead.
[2024-10-04T13:53:42.134+0000] {configuration.py:1053} WARNING - section/key [smtp/smtp_user] not found in config
[2024-10-04T13:53:42.134+0000] {email.py:271} INFO - Email alerting: attempt 1
[2024-10-04T13:53:42.140+0000] {configuration.py:1053} WARNING - section/key [smtp/smtp_user] not found in config
[2024-10-04T13:53:42.141+0000] {email.py:271} INFO - Email alerting: attempt 1
[2024-10-04T13:53:42.141+0000] {taskinstance.py:879} ERROR - Failed to send email to: alexvlg34@gmail.com
Traceback (most recent call last):
  File "/home/airflow/.local/lib/python3.10/site-packages/airflow/models/taskinstance.py", line 2479, in _run_raw_task
    self._execute_task_with_callbacks(context, test_mode, session=session)
  File "/home/airflow/.local/lib/python3.10/site-packages/airflow/models/taskinstance.py", line 2676, in _execute_task_with_callbacks
    result = self._execute_task(context, task_orig)
  File "/home/airflow/.local/lib/python3.10/site-packages/airflow/models/taskinstance.py", line 2701, in _execute_task
    return _execute_task(self, context, task_orig)
  File "/home/airflow/.local/lib/python3.10/site-packages/airflow/models/taskinstance.py", line 465, in _execute_task
    result = _execute_callable(context=context, **execute_callable_kwargs)
  File "/home/airflow/.local/lib/python3.10/site-packages/airflow/models/taskinstance.py", line 432, in _execute_callable
    return execute_callable(context=context, **execute_callable_kwargs)
  File "/home/airflow/.local/lib/python3.10/site-packages/airflow/models/baseoperator.py", line 401, in wrapper
    return func(self, *args, **kwargs)
  File "/home/airflow/.local/lib/python3.10/site-packages/airflow/operators/python.py", line 235, in execute
    return_value = self.execute_callable()
  File "/home/airflow/.local/lib/python3.10/site-packages/airflow/operators/python.py", line 252, in execute_callable
    return self.python_callable(*self.op_args, **self.op_kwargs)
  File "/opt/airflow/dags/airflow/dags/.ipynb_checkpoints/project-checkpoint.py", line 111, in init
    exp_id = mlflow.create_experiment(name="Alex Trigolos project")
  File "/home/airflow/.local/lib/python3.10/site-packages/mlflow/tracking/fluent.py", line 1766, in create_experiment
    return MlflowClient().create_experiment(name, artifact_location, tags)
  File "/home/airflow/.local/lib/python3.10/site-packages/mlflow/tracking/client.py", line 1294, in create_experiment
    return self._tracking_client.create_experiment(name, artifact_location, tags)
  File "/home/airflow/.local/lib/python3.10/site-packages/mlflow/tracking/_tracking_service/client.py", line 501, in create_experiment
    return self.store.create_experiment(
  File "/home/airflow/.local/lib/python3.10/site-packages/mlflow/store/tracking/rest_store.py", line 122, in create_experiment
    response_proto = self._call_endpoint(CreateExperiment, req_body)
  File "/home/airflow/.local/lib/python3.10/site-packages/mlflow/store/tracking/rest_store.py", line 81, in _call_endpoint
    return call_endpoint(self.get_host_creds(), endpoint, method, json_body, response_proto)
  File "/home/airflow/.local/lib/python3.10/site-packages/mlflow/utils/rest_utils.py", line 362, in call_endpoint
    response = verify_rest_response(response, endpoint)
  File "/home/airflow/.local/lib/python3.10/site-packages/mlflow/utils/rest_utils.py", line 232, in verify_rest_response
    raise RestException(json.loads(response.text))
mlflow.exceptions.RestException: RESOURCE_ALREADY_EXISTS: Experiment 'Alex Trigolos project' already exists in deleted state. You can restore the experiment, or permanently delete the experiment from the .trash folder (under tracking server's root folder) in order to use this experiment name again.

During handling of the above exception, another exception occurred:

Traceback (most recent call last):
  File "/home/airflow/.local/lib/python3.10/site-packages/airflow/models/taskinstance.py", line 1063, in _email_alert
    send_email(task.email, subject, html_content)
  File "/home/airflow/.local/lib/python3.10/site-packages/airflow/utils/email.py", line 80, in send_email
    return backend(
  File "/home/airflow/.local/lib/python3.10/site-packages/airflow/utils/email.py", line 154, in send_email_smtp
    send_mime_email(e_from=mail_from, e_to=recipients, mime_msg=msg, conn_id=conn_id, dryrun=dryrun)
  File "/home/airflow/.local/lib/python3.10/site-packages/airflow/utils/email.py", line 273, in send_mime_email
    smtp_conn = _get_smtp_connection(smtp_host, smtp_port, smtp_timeout, smtp_ssl)
  File "/home/airflow/.local/lib/python3.10/site-packages/airflow/utils/email.py", line 317, in _get_smtp_connection
    return smtplib.SMTP(host=host, port=port, timeout=timeout)
  File "/usr/local/lib/python3.10/smtplib.py", line 255, in __init__
    (code, msg) = self.connect(host, port)
  File "/usr/local/lib/python3.10/smtplib.py", line 341, in connect
    self.sock = self._get_socket(host, port, self.timeout)
  File "/usr/local/lib/python3.10/smtplib.py", line 312, in _get_socket
    return socket.create_connection((host, port), timeout,
  File "/usr/local/lib/python3.10/socket.py", line 845, in create_connection
    raise err
  File "/usr/local/lib/python3.10/socket.py", line 833, in create_connection
    sock.connect(sa)
ConnectionRefusedError: [Errno 111] Connection refused

During handling of the above exception, another exception occurred:

Traceback (most recent call last):
  File "/home/airflow/.local/lib/python3.10/site-packages/airflow/models/taskinstance.py", line 877, in _handle_failure
    task_instance.email_alert(error, failure_context["task"])
  File "/home/airflow/.local/lib/python3.10/site-packages/airflow/models/taskinstance.py", line 3163, in email_alert
    _email_alert(task_instance=self, exception=exception, task=task)
  File "/home/airflow/.local/lib/python3.10/site-packages/airflow/models/taskinstance.py", line 1065, in _email_alert
    send_email(task.email, subject, html_content_err)
  File "/home/airflow/.local/lib/python3.10/site-packages/airflow/utils/email.py", line 80, in send_email
    return backend(
  File "/home/airflow/.local/lib/python3.10/site-packages/airflow/utils/email.py", line 154, in send_email_smtp
    send_mime_email(e_from=mail_from, e_to=recipients, mime_msg=msg, conn_id=conn_id, dryrun=dryrun)
  File "/home/airflow/.local/lib/python3.10/site-packages/airflow/utils/email.py", line 273, in send_mime_email
    smtp_conn = _get_smtp_connection(smtp_host, smtp_port, smtp_timeout, smtp_ssl)
  File "/home/airflow/.local/lib/python3.10/site-packages/airflow/utils/email.py", line 317, in _get_smtp_connection
    return smtplib.SMTP(host=host, port=port, timeout=timeout)
  File "/usr/local/lib/python3.10/smtplib.py", line 255, in __init__
    (code, msg) = self.connect(host, port)
  File "/usr/local/lib/python3.10/smtplib.py", line 341, in connect
    self.sock = self._get_socket(host, port, self.timeout)
  File "/usr/local/lib/python3.10/smtplib.py", line 312, in _get_socket
    return socket.create_connection((host, port), timeout,
  File "/usr/local/lib/python3.10/socket.py", line 845, in create_connection
    raise err
  File "/usr/local/lib/python3.10/socket.py", line 833, in create_connection
    sock.connect(sa)
ConnectionRefusedError: [Errno 111] Connection refused
[2024-10-04T13:53:42.153+0000] {standard_task_runner.py:110} ERROR - Failed to execute job 897 for task task_init (RESOURCE_ALREADY_EXISTS: Experiment 'Alex Trigolos project' already exists in deleted state. You can restore the experiment, or permanently delete the experiment from the .trash folder (under tracking server's root folder) in order to use this experiment name again.; 97497)
[2024-10-04T13:53:42.189+0000] {local_task_job_runner.py:243} INFO - Task exited with return code 1
[2024-10-04T13:53:42.209+0000] {taskinstance.py:3503} INFO - 0 downstream tasks scheduled from follow-on schedule check
[2024-10-04T13:53:42.213+0000] {local_task_job_runner.py:222} INFO - ::endgroup::
