[2024-09-24T18:45:52.731+0000] {local_task_job_runner.py:120} INFO - ::group::Pre task execution logs
[2024-09-24T18:45:52.745+0000] {taskinstance.py:2076} INFO - Dependencies all met for dep_context=non-requeueable deps ti=<TaskInstance: decision_tree_classifier_dag.dtc_train_model manual__2024-09-24T18:45:43.038484+00:00 [queued]>
[2024-09-24T18:45:52.751+0000] {taskinstance.py:2076} INFO - Dependencies all met for dep_context=requeueable deps ti=<TaskInstance: decision_tree_classifier_dag.dtc_train_model manual__2024-09-24T18:45:43.038484+00:00 [queued]>
[2024-09-24T18:45:52.752+0000] {taskinstance.py:2306} INFO - Starting attempt 1 of 1
[2024-09-24T18:45:52.760+0000] {taskinstance.py:2330} INFO - Executing <Task(PythonOperator): dtc_train_model> on 2024-09-24 18:45:43.038484+00:00
[2024-09-24T18:45:52.768+0000] {standard_task_runner.py:64} INFO - Started process 46020 to run task
[2024-09-24T18:45:52.770+0000] {standard_task_runner.py:90} INFO - Running: ['***', 'tasks', 'run', 'decision_tree_classifier_dag', 'dtc_train_model', 'manual__2024-09-24T18:45:43.038484+00:00', '--job-id', '448', '--raw', '--subdir', 'DAGS_FOLDER/***/dags/.ipynb_checkpoints/hw1-checkpoint.py', '--cfg-path', '/tmp/tmpjy7r3r4p']
[2024-09-24T18:45:52.772+0000] {standard_task_runner.py:91} INFO - Job 448: Subtask dtc_train_model
[2024-09-24T18:45:52.806+0000] {task_command.py:426} INFO - Running <TaskInstance: decision_tree_classifier_dag.dtc_train_model manual__2024-09-24T18:45:43.038484+00:00 [running]> on host 82997fc6deb7
[2024-09-24T18:45:52.868+0000] {taskinstance.py:2648} INFO - Exporting env vars: AIRFLOW_CTX_DAG_EMAIL='alexvlg34@gmail.com' AIRFLOW_CTX_DAG_OWNER='Alex Trigolos' AIRFLOW_CTX_DAG_ID='decision_tree_classifier_dag' AIRFLOW_CTX_TASK_ID='dtc_train_model' AIRFLOW_CTX_EXECUTION_DATE='2024-09-24T18:45:43.038484+00:00' AIRFLOW_CTX_TRY_NUMBER='1' AIRFLOW_CTX_DAG_RUN_ID='manual__2024-09-24T18:45:43.038484+00:00'
[2024-09-24T18:45:52.869+0000] {taskinstance.py:430} INFO - ::endgroup::
[2024-09-24T18:45:52.878+0000] {hw1-checkpoint.py:127} INFO - Train model...
[2024-09-24T18:45:52.878+0000] {s3.py:1422} INFO - Downloading source S3 file from Bucket testmlops with path AlexTrigolos/DecisionTreeClassifier/datasets/X_train.pkl
[2024-09-24T18:45:52.885+0000] {base.py:84} INFO - Using connection ID 's3_connection' for task execution.
[2024-09-24T18:45:52.886+0000] {connection_wrapper.py:388} INFO - AWS Connection (conn_id='s3_connection', conn_type='aws') credentials retrieved from login and password.
[2024-09-24T18:45:53.295+0000] {hw1-checkpoint.py:53} INFO - /tmp/***_tmp_ktej4o2m
[2024-09-24T18:45:53.298+0000] {s3.py:1422} INFO - Downloading source S3 file from Bucket testmlops with path AlexTrigolos/DecisionTreeClassifier/datasets/X_test.pkl
[2024-09-24T18:45:53.304+0000] {base.py:84} INFO - Using connection ID 's3_connection' for task execution.
[2024-09-24T18:45:53.305+0000] {connection_wrapper.py:388} INFO - AWS Connection (conn_id='s3_connection', conn_type='aws') credentials retrieved from login and password.
[2024-09-24T18:45:53.459+0000] {hw1-checkpoint.py:53} INFO - /tmp/***_tmp_7cnqtvop
[2024-09-24T18:45:53.461+0000] {s3.py:1422} INFO - Downloading source S3 file from Bucket testmlops with path AlexTrigolos/DecisionTreeClassifier/datasets/y_train.pkl
[2024-09-24T18:45:53.467+0000] {base.py:84} INFO - Using connection ID 's3_connection' for task execution.
[2024-09-24T18:45:53.469+0000] {connection_wrapper.py:388} INFO - AWS Connection (conn_id='s3_connection', conn_type='aws') credentials retrieved from login and password.
[2024-09-24T18:45:53.936+0000] {hw1-checkpoint.py:53} INFO - /tmp/***_tmp_6zxlftmg
[2024-09-24T18:45:53.939+0000] {s3.py:1422} INFO - Downloading source S3 file from Bucket testmlops with path AlexTrigolos/DecisionTreeClassifier/datasets/y_test.pkl
[2024-09-24T18:45:53.946+0000] {base.py:84} INFO - Using connection ID 's3_connection' for task execution.
[2024-09-24T18:45:53.947+0000] {connection_wrapper.py:388} INFO - AWS Connection (conn_id='s3_connection', conn_type='aws') credentials retrieved from login and password.
[2024-09-24T18:45:54.287+0000] {hw1-checkpoint.py:53} INFO - /tmp/***_tmp_cgryj88g
[2024-09-24T18:45:54.292+0000] {logging_mixin.py:188} INFO - Fitting 5 folds for each of 4 candidates, totalling 20 fits
[2024-09-24T18:45:54.297+0000] {taskinstance.py:441} INFO - ::group::Post task execution logs
[2024-09-24T18:45:54.298+0000] {taskinstance.py:2905} ERROR - Task failed with exception
Traceback (most recent call last):
  File "/home/airflow/.local/lib/python3.10/site-packages/airflow/models/taskinstance.py", line 465, in _execute_task
    result = _execute_callable(context=context, **execute_callable_kwargs)
  File "/home/airflow/.local/lib/python3.10/site-packages/airflow/models/taskinstance.py", line 432, in _execute_callable
    return execute_callable(context=context, **execute_callable_kwargs)
  File "/home/airflow/.local/lib/python3.10/site-packages/airflow/models/baseoperator.py", line 401, in wrapper
    return func(self, *args, **kwargs)
  File "/home/airflow/.local/lib/python3.10/site-packages/airflow/operators/python.py", line 235, in execute
    return_value = self.execute_callable()
  File "/home/airflow/.local/lib/python3.10/site-packages/airflow/operators/python.py", line 252, in execute_callable
    return self.python_callable(*self.op_args, **self.op_kwargs)
  File "/opt/airflow/dags/airflow/dags/.ipynb_checkpoints/hw1-checkpoint.py", line 177, in train_model
    grid_search.fit(X_train, y_train)
  File "/home/airflow/.local/lib/python3.10/site-packages/sklearn/base.py", line 1473, in wrapper
    return fit_method(estimator, *args, **kwargs)
  File "/home/airflow/.local/lib/python3.10/site-packages/sklearn/model_selection/_search.py", line 1018, in fit
    self._run_search(evaluate_candidates)
  File "/home/airflow/.local/lib/python3.10/site-packages/sklearn/model_selection/_search.py", line 1572, in _run_search
    evaluate_candidates(ParameterGrid(self.param_grid))
  File "/home/airflow/.local/lib/python3.10/site-packages/sklearn/model_selection/_search.py", line 964, in evaluate_candidates
    out = parallel(
  File "/home/airflow/.local/lib/python3.10/site-packages/sklearn/utils/parallel.py", line 74, in __call__
    return super().__call__(iterable_with_config)
  File "/home/airflow/.local/lib/python3.10/site-packages/joblib/parallel.py", line 1918, in __call__
    return output if self.return_generator else list(output)
  File "/home/airflow/.local/lib/python3.10/site-packages/joblib/parallel.py", line 1847, in _get_sequential_output
    res = func(*args, **kwargs)
  File "/home/airflow/.local/lib/python3.10/site-packages/sklearn/utils/parallel.py", line 136, in __call__
    return self.function(*args, **kwargs)
  File "/home/airflow/.local/lib/python3.10/site-packages/sklearn/model_selection/_validation.py", line 876, in _fit_and_score
    estimator = estimator.set_params(**clone(parameters, safe=False))
  File "/home/airflow/.local/lib/python3.10/site-packages/sklearn/base.py", line 279, in set_params
    raise ValueError(
ValueError: Invalid parameter 'n_estimators' for estimator DecisionTreeClassifier(min_samples_split=1). Valid parameters are: ['ccp_alpha', 'class_weight', 'criterion', 'max_depth', 'max_features', 'max_leaf_nodes', 'min_impurity_decrease', 'min_samples_leaf', 'min_samples_split', 'min_weight_fraction_leaf', 'monotonic_cst', 'random_state', 'splitter'].
[2024-09-24T18:45:54.313+0000] {taskinstance.py:1206} INFO - Marking task as FAILED. dag_id=decision_tree_classifier_dag, task_id=dtc_train_model, run_id=manual__2024-09-24T18:45:43.038484+00:00, execution_date=20240924T184543, start_date=20240924T184552, end_date=20240924T184554
[2024-09-24T18:45:54.326+0000] {logging_mixin.py:188} WARNING - /home/***/.local/lib/python3.10/site-packages/***/utils/email.py:154 RemovedInAirflow3Warning: Fetching SMTP credentials from configuration variables will be deprecated in a future release. Please set credentials using a connection instead.
[2024-09-24T18:45:54.327+0000] {configuration.py:1053} WARNING - section/key [smtp/smtp_user] not found in config
[2024-09-24T18:45:54.327+0000] {email.py:271} INFO - Email alerting: attempt 1
[2024-09-24T18:45:54.333+0000] {configuration.py:1053} WARNING - section/key [smtp/smtp_user] not found in config
[2024-09-24T18:45:54.334+0000] {email.py:271} INFO - Email alerting: attempt 1
[2024-09-24T18:45:54.334+0000] {taskinstance.py:879} ERROR - Failed to send email to: alexvlg34@gmail.com
Traceback (most recent call last):
  File "/home/airflow/.local/lib/python3.10/site-packages/airflow/models/taskinstance.py", line 2479, in _run_raw_task
    self._execute_task_with_callbacks(context, test_mode, session=session)
  File "/home/airflow/.local/lib/python3.10/site-packages/airflow/models/taskinstance.py", line 2676, in _execute_task_with_callbacks
    result = self._execute_task(context, task_orig)
  File "/home/airflow/.local/lib/python3.10/site-packages/airflow/models/taskinstance.py", line 2701, in _execute_task
    return _execute_task(self, context, task_orig)
  File "/home/airflow/.local/lib/python3.10/site-packages/airflow/models/taskinstance.py", line 465, in _execute_task
    result = _execute_callable(context=context, **execute_callable_kwargs)
  File "/home/airflow/.local/lib/python3.10/site-packages/airflow/models/taskinstance.py", line 432, in _execute_callable
    return execute_callable(context=context, **execute_callable_kwargs)
  File "/home/airflow/.local/lib/python3.10/site-packages/airflow/models/baseoperator.py", line 401, in wrapper
    return func(self, *args, **kwargs)
  File "/home/airflow/.local/lib/python3.10/site-packages/airflow/operators/python.py", line 235, in execute
    return_value = self.execute_callable()
  File "/home/airflow/.local/lib/python3.10/site-packages/airflow/operators/python.py", line 252, in execute_callable
    return self.python_callable(*self.op_args, **self.op_kwargs)
  File "/opt/airflow/dags/airflow/dags/.ipynb_checkpoints/hw1-checkpoint.py", line 177, in train_model
    grid_search.fit(X_train, y_train)
  File "/home/airflow/.local/lib/python3.10/site-packages/sklearn/base.py", line 1473, in wrapper
    return fit_method(estimator, *args, **kwargs)
  File "/home/airflow/.local/lib/python3.10/site-packages/sklearn/model_selection/_search.py", line 1018, in fit
    self._run_search(evaluate_candidates)
  File "/home/airflow/.local/lib/python3.10/site-packages/sklearn/model_selection/_search.py", line 1572, in _run_search
    evaluate_candidates(ParameterGrid(self.param_grid))
  File "/home/airflow/.local/lib/python3.10/site-packages/sklearn/model_selection/_search.py", line 964, in evaluate_candidates
    out = parallel(
  File "/home/airflow/.local/lib/python3.10/site-packages/sklearn/utils/parallel.py", line 74, in __call__
    return super().__call__(iterable_with_config)
  File "/home/airflow/.local/lib/python3.10/site-packages/joblib/parallel.py", line 1918, in __call__
    return output if self.return_generator else list(output)
  File "/home/airflow/.local/lib/python3.10/site-packages/joblib/parallel.py", line 1847, in _get_sequential_output
    res = func(*args, **kwargs)
  File "/home/airflow/.local/lib/python3.10/site-packages/sklearn/utils/parallel.py", line 136, in __call__
    return self.function(*args, **kwargs)
  File "/home/airflow/.local/lib/python3.10/site-packages/sklearn/model_selection/_validation.py", line 876, in _fit_and_score
    estimator = estimator.set_params(**clone(parameters, safe=False))
  File "/home/airflow/.local/lib/python3.10/site-packages/sklearn/base.py", line 279, in set_params
    raise ValueError(
ValueError: Invalid parameter 'n_estimators' for estimator DecisionTreeClassifier(min_samples_split=1). Valid parameters are: ['ccp_alpha', 'class_weight', 'criterion', 'max_depth', 'max_features', 'max_leaf_nodes', 'min_impurity_decrease', 'min_samples_leaf', 'min_samples_split', 'min_weight_fraction_leaf', 'monotonic_cst', 'random_state', 'splitter'].

During handling of the above exception, another exception occurred:

Traceback (most recent call last):
  File "/home/airflow/.local/lib/python3.10/site-packages/airflow/models/taskinstance.py", line 1063, in _email_alert
    send_email(task.email, subject, html_content)
  File "/home/airflow/.local/lib/python3.10/site-packages/airflow/utils/email.py", line 80, in send_email
    return backend(
  File "/home/airflow/.local/lib/python3.10/site-packages/airflow/utils/email.py", line 154, in send_email_smtp
    send_mime_email(e_from=mail_from, e_to=recipients, mime_msg=msg, conn_id=conn_id, dryrun=dryrun)
  File "/home/airflow/.local/lib/python3.10/site-packages/airflow/utils/email.py", line 273, in send_mime_email
    smtp_conn = _get_smtp_connection(smtp_host, smtp_port, smtp_timeout, smtp_ssl)
  File "/home/airflow/.local/lib/python3.10/site-packages/airflow/utils/email.py", line 317, in _get_smtp_connection
    return smtplib.SMTP(host=host, port=port, timeout=timeout)
  File "/usr/local/lib/python3.10/smtplib.py", line 255, in __init__
    (code, msg) = self.connect(host, port)
  File "/usr/local/lib/python3.10/smtplib.py", line 341, in connect
    self.sock = self._get_socket(host, port, self.timeout)
  File "/usr/local/lib/python3.10/smtplib.py", line 312, in _get_socket
    return socket.create_connection((host, port), timeout,
  File "/usr/local/lib/python3.10/socket.py", line 845, in create_connection
    raise err
  File "/usr/local/lib/python3.10/socket.py", line 833, in create_connection
    sock.connect(sa)
ConnectionRefusedError: [Errno 111] Connection refused

During handling of the above exception, another exception occurred:

Traceback (most recent call last):
  File "/home/airflow/.local/lib/python3.10/site-packages/airflow/models/taskinstance.py", line 877, in _handle_failure
    task_instance.email_alert(error, failure_context["task"])
  File "/home/airflow/.local/lib/python3.10/site-packages/airflow/models/taskinstance.py", line 3163, in email_alert
    _email_alert(task_instance=self, exception=exception, task=task)
  File "/home/airflow/.local/lib/python3.10/site-packages/airflow/models/taskinstance.py", line 1065, in _email_alert
    send_email(task.email, subject, html_content_err)
  File "/home/airflow/.local/lib/python3.10/site-packages/airflow/utils/email.py", line 80, in send_email
    return backend(
  File "/home/airflow/.local/lib/python3.10/site-packages/airflow/utils/email.py", line 154, in send_email_smtp
    send_mime_email(e_from=mail_from, e_to=recipients, mime_msg=msg, conn_id=conn_id, dryrun=dryrun)
  File "/home/airflow/.local/lib/python3.10/site-packages/airflow/utils/email.py", line 273, in send_mime_email
    smtp_conn = _get_smtp_connection(smtp_host, smtp_port, smtp_timeout, smtp_ssl)
  File "/home/airflow/.local/lib/python3.10/site-packages/airflow/utils/email.py", line 317, in _get_smtp_connection
    return smtplib.SMTP(host=host, port=port, timeout=timeout)
  File "/usr/local/lib/python3.10/smtplib.py", line 255, in __init__
    (code, msg) = self.connect(host, port)
  File "/usr/local/lib/python3.10/smtplib.py", line 341, in connect
    self.sock = self._get_socket(host, port, self.timeout)
  File "/usr/local/lib/python3.10/smtplib.py", line 312, in _get_socket
    return socket.create_connection((host, port), timeout,
  File "/usr/local/lib/python3.10/socket.py", line 845, in create_connection
    raise err
  File "/usr/local/lib/python3.10/socket.py", line 833, in create_connection
    sock.connect(sa)
ConnectionRefusedError: [Errno 111] Connection refused
[2024-09-24T18:45:54.351+0000] {standard_task_runner.py:110} ERROR - Failed to execute job 448 for task dtc_train_model (Invalid parameter 'n_estimators' for estimator DecisionTreeClassifier(min_samples_split=1). Valid parameters are: ['ccp_alpha', 'class_weight', 'criterion', 'max_depth', 'max_features', 'max_leaf_nodes', 'min_impurity_decrease', 'min_samples_leaf', 'min_samples_split', 'min_weight_fraction_leaf', 'monotonic_cst', 'random_state', 'splitter'].; 46020)
[2024-09-24T18:45:54.390+0000] {local_task_job_runner.py:243} INFO - Task exited with return code 1
[2024-09-24T18:45:54.408+0000] {taskinstance.py:3503} INFO - 0 downstream tasks scheduled from follow-on schedule check
[2024-09-24T18:45:54.413+0000] {local_task_job_runner.py:222} INFO - ::endgroup::
